Workbook

Sheet 주문 요약
A1: JOSHUA GENERATION · PROMISED LAND JAPAN IN OITA
A2: 공동체 단체 주문서
A3: 작성 순서 ① 아래 노란 칸에 공동체 정보 입력 ② 「개인별 주문」 시트에 주문 입력 ③ 수량·금액은 자동 계산됨 → 「입력 확인」이 ✓인지 확인 후 파일 그대로 회신
A5: 공동체 정보
A6: 공동체명
A7: 담당자 이름
A8: 담당자 연락처
A9: 받는 분 (배송)
A10: 배송지 주소
A11: 입금자명
A12: 입금 예정일
A14: 결제 요약
A15: 정가 기준 합계 | D15: =SUMPRODUCT('개인별 주문'!$I$6:$I$305,'개인별 주문'!$H$6:$H$305) -> 0
A16: 사전구매 할인액 (10%) | D16: =D15-D17 -> 0
A17: 총 입금액 (10% 할인 적용) | D17: =SUM('개인별 주문'!$K$6:$K$305) -> 0
A19: 입력 확인 | C19: =IF(COUNTIF('개인별 주문'!$L$6:$L$305,"<>OK")-COUNTIF('개인별 주문'!$L$6:$L$305,"")>0,"⚠ 「개인별 주문」 시트에 확인이 필요한 줄이 있어요","✓ 입력 오류 없음") -> ✓ 입력 오류 없음
A21: 의류 (사이즈별 수량)
A22: 상품 | B22: XXS | C22: XS | D22: S | E22: M | F22: L | G22: XL | H22: 2XL | I22: 3XL | J22: 수량 | K22: 금액
A23: 후드집업 - 그레이 | B23: - | C23: - | D23: =SUMIFS('개인별 주문'!$H$6:$H$305,'개인별 주문'!$C$6:$C$305,$A23,'개인별 주문'!$D$6:$D$305,D$22) -> 0 | E23: =SUMIFS('개인별 주문'!$H$6:$H$305,'개인별 주문'!$C$6:$C$305,$A23,'개인별 주문'!$D$6:$D$305,E$22) -> 0 | F23: =SUMIFS('개인별 주문'!$H$6:$H$305,'개인별 주문'!$C$6:$C$305,$A23,'개인별 주문'!$D$6:$D$305,F$22) -> 0 | G23: =SUMIFS('개인별 주문'!$H$6:$H$305,'개인별 주문'!$C$6:$C$305,$A23,'개인별 주문'!$D$6:$D$305,G$22) -> 0 | H23: =SUMIFS('개인별 주문'!$H$6:$H$305,'개인별 주문'!$C$6:$C$305,$A23,'개인별 주문'!$D$6:$D$305,H$22) -> 0 | I23: =SUMIFS('개인별 주문'!$H$6:$H$305,'개인별 주문'!$C$6:$C$305,$A23,'개인별 주문'!$D$6:$D$305,I$22) -> 0 | J23: =SUM(B23:I23) -> 0 | K23: =SUMIFS('개인별 주문'!$K$6:$K$305,'개인별 주문'!$C$6:$C$305,$A23) -> 0
A24: 후드집업 - 블랙 | B24: - | C24: - | D24: =SUMIFS('개인별 주문'!$H$6:$H$305,'개인별 주문'!$C$6:$C$305,$A24,'개인별 주문'!$D$6:$D$305,D$22) -> 0 | E24: =SUMIFS('개인별 주문'!$H$6:$H$305,'개인별 주문'!$C$6:$C$305,$A24,'개인별 주문'!$D$6:$D$305,E$22) -> 0 | F24: =SUMIFS('개인별 주문'!$H$6:$H$305,'개인별 주문'!$C$6:$C$305,$A24,'개인별 주문'!$D$6:$D$305,F$22) -> 0 | G24: =SUMIFS('개인별 주문'!$H$6:$H$305,'개인별 주문'!$C$6:$C$305,$A24,'개인별 주문'!$D$6:$D$305,G$22) -> 0 | H24: =SUMIFS('개인별 주문'!$H$6:$H$305,'개인별 주문'!$C$6:$C$305,$A24,'개인별 주문'!$D$6:$D$305,H$22) -> 0 | I24: =SUMIFS('개인별 주문'!$H$6:$H$305,'개인별 주문'!$C$6:$C$305,$A24,'개인별 주문'!$D$6:$D$305,I$22) -> 0 | J24: =SUM(B24:I24) -> 0 | K24: =SUMIFS('개인별 주문'!$K$6:$K$305,'개인별 주문'!$C$6:$C$305,$A24) -> 0
A25: 그래픽 티셔츠 - 블랙 | B25: =SUMIFS('개인별 주문'!$H$6:$H$305,'개인별 주문'!$C$6:$C$305,$A25,'개인별 주문'!$D$6:$D$305,B$22) -> 0 | C25: =SUMIFS('개인별 주문'!$H$6:$H$305,'개인별 주문'!$C$6:$C$305,$A25,'개인별 주문'!$D$6:$D$305,C$22) -> 0 | D25: =SUMIFS('개인별 주문'!$H$6:$H$305,'개인별 주문'!$C$6:$C$305,$A25,'개인별 주문'!$D$6:$D$305,D$22) -> 0 | E25: =SUMIFS('개인별 주문'!$H$6:$H$305,'개인별 주문'!$C$6:$C$305,$A25,'개인별 주문'!$D$6:$D$305,E$22) -> 0 | F25: =SUMIFS('개인별 주문'!$H$6:$H$305,'개인별 주문'!$C$6:$C$305,$A25,'개인별 주문'!$D$6:$D$305,F$22) -> 0 | G25: =SUMIFS('개인별 주문'!$H$6:$H$305,'개인별 주문'!$C$6:$C$305,$A25,'개인별 주문'!$D$6:$D$305,G$22) -> 0 | H25: =SUMIFS('개인별 주문'!$H$6:$H$305,'개인별 주문'!$C$6:$C$305,$A25,'개인별 주문'!$D$6:$D$305,H$22) -> 0 | I25: =SUMIFS('개인별 주문'!$H$6:$H$305,'개인별 주문'!$C$6:$C$305,$A25,'개인별 주문'!$D$6:$D$305,I$22) -> 0 | J25: =SUM(B25:I25) -> 0 | K25: =SUMIFS('개인별 주문'!$K$6:$K$305,'개인별 주문'!$C$6:$C$305,$A25) -> 0
A26: 그래픽 티셔츠 - 화이트 | B26: =SUMIFS('개인별 주문'!$H$6:$H$305,'개인별 주문'!$C$6:$C$305,$A26,'개인별 주문'!$D$6:$D$305,B$22) -> 0 | C26: =SUMIFS('개인별 주문'!$H$6:$H$305,'개인별 주문'!$C$6:$C$305,$A26,'개인별 주문'!$D$6:$D$305,C$22) -> 0 | D26: =SUMIFS('개인별 주문'!$H$6:$H$305,'개인별 주문'!$C$6:$C$305,$A26,'개인별 주문'!$D$6:$D$305,D$22) -> 0 | E26: =SUMIFS('개인별 주문'!$H$6:$H$305,'개인별 주문'!$C$6:$C$305,$A26,'개인별 주문'!$D$6:$D$305,E$22) -> 0 | F26: =SUMIFS('개인별 주문'!$H$6:$H$305,'개인별 주문'!$C$6:$C$305,$A26,'개인별 주문'!$D$6:$D$305,F$22) -> 0 | G26: =SUMIFS('개인별 주문'!$H$6:$H$305,'개인별 주문'!$C$6:$C$305,$A26,'개인별 주문'!$D$6:$D$305,G$22) -> 0 | H26: =SUMIFS('개인별 주문'!$H$6:$H$305,'개인별 주문'!$C$6:$C$305,$A26,'개인별 주문'!$D$6:$D$305,H$22) -> 0 | I26: =SUMIFS('개인별 주문'!$H$6:$H$305,'개인별 주문'!$C$6:$C$305,$A26,'개인별 주문'!$D$6:$D$305,I$22) -> 0 | J26: =SUM(B26:I26) -> 0 | K26: =SUMIFS('개인별 주문'!$K$6:$K$305,'개인별 주문'!$C$6:$C$305,$A26) -> 0
A28: 굿즈 · 올인원 세트
A29: 상품 | J29: 수량 | K29: 금액
A30: 손수건 - 레드 웨이브 | J30: =SUMIFS('개인별 주문'!$H$6:$H$305,'개인별 주문'!$C$6:$C$305,$A30) -> 0 | K30: =SUMIFS('개인별 주문'!$K$6:$K$305,'개인별 주문'!$C$6:$C$305,$A30) -> 0
A31: 손수건 - 블랙 스탬프 | J31: =SUMIFS('개인별 주문'!$H$6:$H$305,'개인별 주문'!$C$6:$C$305,$A31) -> 0 | K31: =SUMIFS('개인별 주문'!$K$6:$K$305,'개인별 주문'!$C$6:$C$305,$A31) -> 0
A32: 바쿠백 - 블랙 | J32: =SUMIFS('개인별 주문'!$H$6:$H$305,'개인별 주문'!$C$6:$C$305,$A32) -> 0 | K32: =SUMIFS('개인별 주문'!$K$6:$K$305,'개인별 주문'!$C$6:$C$305,$A32) -> 0
A33: 바쿠백 - 화이트 | J33: =SUMIFS('개인별 주문'!$H$6:$H$305,'개인별 주문'!$C$6:$C$305,$A33) -> 0 | K33: =SUMIFS('개인별 주문'!$K$6:$K$305,'개인별 주문'!$C$6:$C$305,$A33) -> 0
A34: 핑거보드 키링 | J34: =SUMIFS('개인별 주문'!$H$6:$H$305,'개인별 주문'!$C$6:$C$305,$A34) -> 0 | K34: =SUMIFS('개인별 주문'!$K$6:$K$305,'개인별 주문'!$C$6:$C$305,$A34) -> 0
A35: 키링 1 - 스탬프 | J35: =SUMIFS('개인별 주문'!$H$6:$H$305,'개인별 주문'!$C$6:$C$305,$A35) -> 0 | K35: =SUMIFS('개인별 주문'!$K$6:$K$305,'개인별 주문'!$C$6:$C$305,$A35) -> 0
A36: 키링 2 - 십자가 | J36: =SUMIFS('개인별 주문'!$H$6:$H$305,'개인별 주문'!$C$6:$C$305,$A36) -> 0 | K36: =SUMIFS('개인별 주문'!$K$6:$K$305,'개인별 주문'!$C$6:$C$305,$A36) -> 0
A37: 네임택 - 블랙 스탬프 | J37: =SUMIFS('개인별 주문'!$H$6:$H$305,'개인별 주문'!$C$6:$C$305,$A37) -> 0 | K37: =SUMIFS('개인별 주문'!$K$6:$K$305,'개인별 주문'!$C$6:$C$305,$A37) -> 0
A38: 네임택 - 웨이브 | J38: =SUMIFS('개인별 주문'!$H$6:$H$305,'개인별 주문'!$C$6:$C$305,$A38) -> 0 | K38: =SUMIFS('개인별 주문'!$K$6:$K$305,'개인별 주문'!$C$6:$C$305,$A38) -> 0
A39: 스티커팩 | J39: =SUMIFS('개인별 주문'!$H$6:$H$305,'개인별 주문'!$C$6:$C$305,$A39) -> 0 | K39: =SUMIFS('개인별 주문'!$K$6:$K$305,'개인별 주문'!$C$6:$C$305,$A39) -> 0
A40: 올인원 세트 | J40: =SUMIFS('개인별 주문'!$H$6:$H$305,'개인별 주문'!$C$6:$C$305,$A40) -> 0 | K40: =SUMIFS('개인별 주문'!$K$6:$K$305,'개인별 주문'!$C$6:$C$305,$A40) -> 0
A41: 합계 | J41: =SUM(J23:J26)+SUM(J30:J40) -> 0 | K41: =SUM(K23:K26)+SUM(K30:K40) -> 0 | L41: =IF(K41=D17,"✓ 총 입금액과 일치","⚠ 확인 필요") -> ✓ 총 입금액과 일치
A43: 디자인별 필요 수량 (낱개 + 세트 구성품) — 포장·발주용
A44: 디자인 | H44: 낱개 주문 | I44: 세트 구성품 | K44: 필요 수량
A45: 손수건 - 레드 웨이브 | H45: =SUMIFS('개인별 주문'!$H$6:$H$305,'개인별 주문'!$C$6:$C$305,$A45) -> 0 | I45: =SUMIFS('개인별 주문'!$H$6:$H$305,'개인별 주문'!$C$6:$C$305,"올인원 세트",'개인별 주문'!$E$6:$E$305,"레드 웨이브") -> 0 | K45: =H45+I45 -> 0
A46: 손수건 - 블랙 스탬프 | H46: =SUMIFS('개인별 주문'!$H$6:$H$305,'개인별 주문'!$C$6:$C$305,$A46) -> 0 | I46: =SUMIFS('개인별 주문'!$H$6:$H$305,'개인별 주문'!$C$6:$C$305,"올인원 세트",'개인별 주문'!$E$6:$E$305,"블랙 스탬프") -> 0 | K46: =H46+I46 -> 0
...

Sheet 개인별 주문
A1: 개인별 주문 입력
A2: 작성 방법 ① 노란 칸만 입력, 한 줄에 상품 하나씩 (한 사람이 여러 개 사면 여러 줄로) ② 상품을 고르면 필요 없는 칸은 회색, 꼭 입력할 칸은 주황색으로 바뀜 → 의류는 사이즈(파란 머리글), 올인원 세트는 반다나·바쿠백·키링(초록 머리글)만 선택 ③ 단체 사전주문은 전 제품 10% 할인가가 자동 적용 ④ 「확인」 칸이 OK가 아니면 빨간 글씨 안내대로 수정
D3: 의류만 | E3: 올인원 세트만
A4: 예시 | B4: 홍길동 | C4: 올인원 세트 | E4: 레드 웨이브 | F4: 화이트 | G4: 1 스탬프 | H4: 1 | I4: 32000 | J4: 28800 | K4: 28800 | L4: OK | M4: 예시 줄 (합계에 안 들어감)
A5: No | B5: 이름 | C5: 상품 | D5: 사이즈 (의류) | E5: 세트: 반다나 | F5: 세트: 바쿠백 | G5: 세트: 키링 | H5: 수량 | I5: 정가 단가 | J5: 할인 단가(10%) | K5: 금액 | L5: 확인 | M5: 메모 | N5: 스탭 확인 (명단 대조)
A6: 1 | I6: {=IF(C6="","",IFERROR(INDEX('상품표'!$C$4:$C$18,MATCH(C6,'상품표'!$A$4:$A$18,0)),""))} | J6: =IF(I6="","",ROUND(I6*(1-'상품표'!$G$4),0)) | K6: =IF(OR(J6="",H6=""),"",J6*H6) | L6: {=IF(C6="","",IF(ISNA(MATCH(C6,'상품표'!$A$4:$A$18,0)),"상품명 확인",IF(H6="","수량 입력",IF(FALSE,"",IF(INDEX('상품표'!$B$4:$B$18,MATCH(C6,'상품표'!$A$4:$A$18,0))="의류",IF(D6="","사이즈 선택",IF(AND(LEFT(C6,4)="후드집업",OR(D6="XXS",D6="XS")),"후드는 S부터",IF(COUNTA(E6:G6)>0,"세트 옵션은 세트만","OK"))),IF(INDEX('상품표'!$B$4:$B$18,MATCH(C6,'상품표'!$A$4:$A$18,0))="세트",IF(COUNTA(E6:G6)<3,"세트 옵션 선택",IF(D6<>"","사이즈 불필요","OK")),IF(COUNTA(E6:G6)>0,"세트 옵션은 세트만",IF(D6<>"","사이즈 불필요","OK"))))))))}
A7: 2 | I7: {=IF(C7="","",IFERROR(INDEX('상품표'!$C$4:$C$18,MATCH(C7,'상품표'!$A$4:$A$18,0)),""))} | J7: =IF(I7="","",ROUND(I7*(1-'상품표'!$G$4),0)) | K7: =IF(OR(J7="",H7=""),"",J7*H7) | L7: {=IF(C7="","",IF(ISNA(MATCH(C7,'상품표'!$A$4:$A$18,0)),"상품명 확인",IF(H7="","수량 입력",IF(FALSE,"",IF(INDEX('상품표'!$B$4:$B$18,MATCH(C7,'상품표'!$A$4:$A$18,0))="의류",IF(D7="","사이즈 선택",IF(AND(LEFT(C7,4)="후드집업",OR(D7="XXS",D7="XS")),"후드는 S부터",IF(COUNTA(E7:G7)>0,"세트 옵션은 세트만","OK"))),IF(INDEX('상품표'!$B$4:$B$18,MATCH(C7,'상품표'!$A$4:$A$18,0))="세트",IF(COUNTA(E7:G7)<3,"세트 옵션 선택",IF(D7<>"","사이즈 불필요","OK")),IF(COUNTA(E7:G7)>0,"세트 옵션은 세트만",IF(D7<>"","사이즈 불필요","OK"))))))))}
A8: 3 | I8: {=IF(C8="","",IFERROR(INDEX('상품표'!$C$4:$C$18,MATCH(C8,'상품표'!$A$4:$A$18,0)),""))} | J8: =IF(I8="","",ROUND(I8*(1-'상품표'!$G$4),0)) | K8: =IF(OR(J8="",H8=""),"",J8*H8) | L8: {=IF(C8="","",IF(ISNA(MATCH(C8,'상품표'!$A$4:$A$18,0)),"상품명 확인",IF(H8="","수량 입력",IF(FALSE,"",IF(INDEX('상품표'!$B$4:$B$18,MATCH(C8,'상품표'!$A$4:$A$18,0))="의류",IF(D8="","사이즈 선택",IF(AND(LEFT(C8,4)="후드집업",OR(D8="XXS",D8="XS")),"후드는 S부터",IF(COUNTA(E8:G8)>0,"세트 옵션은 세트만","OK"))),IF(INDEX('상품표'!$B$4:$B$18,MATCH(C8,'상품표'!$A$4:$A$18,0))="세트",IF(COUNTA(E8:G8)<3,"세트 옵션 선택",IF(D8<>"","사이즈 불필요","OK")),IF(COUNTA(E8:G8)>0,"세트 옵션은 세트만",IF(D8<>"","사이즈 불필요","OK"))))))))}
A9: 4 | I9: {=IF(C9="","",IFERROR(INDEX('상품표'!$C$4:$C$18,MATCH(C9,'상품표'!$A$4:$A$18,0)),""))} | J9: =IF(I9="","",ROUND(I9*(1-'상품표'!$G$4),0)) | K9: =IF(OR(J9="",H9=""),"",J9*H9) | L9: {=IF(C9="","",IF(ISNA(MATCH(C9,'상품표'!$A$4:$A$18,0)),"상품명 확인",IF(H9="","수량 입력",IF(FALSE,"",IF(INDEX('상품표'!$B$4:$B$18,MATCH(C9,'상품표'!$A$4:$A$18,0))="의류",IF(D9="","사이즈 선택",IF(AND(LEFT(C9,4)="후드집업",OR(D9="XXS",D9="XS")),"후드는 S부터",IF(COUNTA(E9:G9)>0,"세트 옵션은 세트만","OK"))),IF(INDEX('상품표'!$B$4:$B$18,MATCH(C9,'상품표'!$A$4:$A$18,0))="세트",IF(COUNTA(E9:G9)<3,"세트 옵션 선택",IF(D9<>"","사이즈 불필요","OK")),IF(COUNTA(E9:G9)>0,"세트 옵션은 세트만",IF(D9<>"","사이즈 불필요","OK"))))))))}
A10: 5 | I10: {=IF(C10="","",IFERROR(INDEX('상품표'!$C$4:$C$18,MATCH(C10,'상품표'!$A$4:$A$18,0)),""))} | J10: =IF(I10="","",ROUND(I10*(1-'상품표'!$G$4),0)) | K10: =IF(OR(J10="",H10=""),"",J10*H10) | L10: {=IF(C10="","",IF(ISNA(MATCH(C10,'상품표'!$A$4:$A$18,0)),"상품명 확인",IF(H10="","수량 입력",IF(FALSE,"",IF(INDEX('상품표'!$B$4:$B$18,MATCH(C10,'상품표'!$A$4:$A$18,0))="의류",IF(D10="","사이즈 선택",IF(AND(LEFT(C10,4)="후드집업",OR(D10="XXS",D10="XS")),"후드는 S부터",IF(COUNTA(E10:G10)>0,"세트 옵션은 세트만","OK"))),IF(INDEX('상품표'!$B$4:$B$18,MATCH(C10,'상품표'!$A$4:$A$18,0))="세트",IF(COUNTA(E10:G10)<3,"세트 옵션 선택",IF(D10<>"","사이즈 불필요","OK")),IF(COUNTA(E10:G10)>0,"세트 옵션은 세트만",IF(D10<>"","사이즈 불필요","OK"))))))))}
A11: 6 | I11: {=IF(C11="","",IFERROR(INDEX('상품표'!$C$4:$C$18,MATCH(C11,'상품표'!$A$4:$A$18,0)),""))} | J11: =IF(I11="","",ROUND(I11*(1-'상품표'!$G$4),0)) | K11: =IF(OR(J11="",H11=""),"",J11*H11) | L11: {=IF(C11="","",IF(ISNA(MATCH(C11,'상품표'!$A$4:$A$18,0)),"상품명 확인",IF(H11="","수량 입력",IF(FALSE,"",IF(INDEX('상품표'!$B$4:$B$18,MATCH(C11,'상품표'!$A$4:$A$18,0))="의류",IF(D11="","사이즈 선택",IF(AND(LEFT(C11,4)="후드집업",OR(D11="XXS",D11="XS")),"후드는 S부터",IF(COUNTA(E11:G11)>0,"세트 옵션은 세트만","OK"))),IF(INDEX('상품표'!$B$4:$B$18,MATCH(C11,'상품표'!$A$4:$A$18,0))="세트",IF(COUNTA(E11:G11)<3,"세트 옵션 선택",IF(D11<>"","사이즈 불필요","OK")),IF(COUNTA(E11:G11)>0,"세트 옵션은 세트만",IF(D11<>"","사이즈 불필요","OK"))))))))}
A12: 7 | I12: {=IF(C12="","",IFERROR(INDEX('상품표'!$C$4:$C$18,MATCH(C12,'상품표'!$A$4:$A$18,0)),""))} | J12: =IF(I12="","",ROUND(I12*(1-'상품표'!$G$4),0)) | K12: =IF(OR(J12="",H12=""),"",J12*H12) | L12: {=IF(C12="","",IF(ISNA(MATCH(C12,'상품표'!$A$4:$A$18,0)),"상품명 확인",IF(H12="","수량 입력",IF(FALSE,"",IF(INDEX('상품표'!$B$4:$B$18,MATCH(C12,'상품표'!$A$4:$A$18,0))="의류",IF(D12="","사이즈 선택",IF(AND(LEFT(C12,4)="후드집업",OR(D12="XXS",D12="XS")),"후드는 S부터",IF(COUNTA(E12:G12)>0,"세트 옵션은 세트만","OK"))),IF(INDEX('상품표'!$B$4:$B$18,MATCH(C12,'상품표'!$A$4:$A$18,0))="세트",IF(COUNTA(E12:G12)<3,"세트 옵션 선택",IF(D12<>"","사이즈 불필요","OK")),IF(COUNTA(E12:G12)>0,"세트 옵션은 세트만",IF(D12<>"","사이즈 불필요","OK"))))))))}
A13: 8 | I13: {=IF(C13="","",IFERROR(INDEX('상품표'!$C$4:$C$18,MATCH(C13,'상품표'!$A$4:$A$18,0)),""))} | J13: =IF(I13="","",ROUND(I13*(1-'상품표'!$G$4),0)) | K13: =IF(OR(J13="",H13=""),"",J13*H13) | L13: {=IF(C13="","",IF(ISNA(MATCH(C13,'상품표'!$A$4:$A$18,0)),"상품명 확인",IF(H13="","수량 입력",IF(FALSE,"",IF(INDEX('상품표'!$B$4:$B$18,MATCH(C13,'상품표'!$A$4:$A$18,0))="의류",IF(D13="","사이즈 선택",IF(AND(LEFT(C13,4)="후드집업",OR(D13="XXS",D13="XS")),"후드는 S부터",IF(COUNTA(E13:G13)>0,"세트 옵션은 세트만","OK"))),IF(INDEX('상품표'!$B$4:$B$18,MATCH(C13,'상품표'!$A$4:$A$18,0))="세트",IF(COUNTA(E13:G13)<3,"세트 옵션 선택",IF(D13<>"","사이즈 불필요","OK")),IF(COUNTA(E13:G13)>0,"세트 옵션은 세트만",IF(D13<>"","사이즈 불필요","OK"))))))))}
A14: 9 | I14: {=IF(C14="","",IFERROR(INDEX('상품표'!$C$4:$C$18,MATCH(C14,'상품표'!$A$4:$A$18,0)),""))} | J14: =IF(I14="","",ROUND(I14*(1-'상품표'!$G$4),0)) | K14: =IF(OR(J14="",H14=""),"",J14*H14) | L14: {=IF(C14="","",IF(ISNA(MATCH(C14,'상품표'!$A$4:$A$18,0)),"상품명 확인",IF(H14="","수량 입력",IF(FALSE,"",IF(INDEX('상품표'!$B$4:$B$18,MATCH(C14,'상품표'!$A$4:$A$18,0))="의류",IF(D14="","사이즈 선택",IF(AND(LEFT(C14,4)="후드집업",OR(D14="XXS",D14="XS")),"후드는 S부터",IF(COUNTA(E14:G14)>0,"세트 옵션은 세트만","OK"))),IF(INDEX('상품표'!$B$4:$B$18,MATCH(C14,'상품표'!$A$4:$A$18,0))="세트",IF(COUNTA(E14:G14)<3,"세트 옵션 선택",IF(D14<>"","사이즈 불필요","OK")),IF(COUNTA(E14:G14)>0,"세트 옵션은 세트만",IF(D14<>"","사이즈 불필요","OK"))))))))}
A15: 10 | I15: {=IF(C15="","",IFERROR(INDEX('상품표'!$C$4:$C$18,MATCH(C15,'상품표'!$A$4:$A$18,0)),""))} | J15: =IF(I15="","",ROUND(I15*(1-'상품표'!$G$4),0)) | K15: =IF(OR(J15="",H15=""),"",J15*H15) | L15: {=IF(C15="","",IF(ISNA(MATCH(C15,'상품표'!$A$4:$A$18,0)),"상품명 확인",IF(H15="","수량 입력",IF(FALSE,"",IF(INDEX('상품표'!$B$4:$B$18,MATCH(C15,'상품표'!$A$4:$A$18,0))="의류",IF(D15="","사이즈 선택",IF(AND(LEFT(C15,4)="후드집업",OR(D15="XXS",D15="XS")),"후드는 S부터",IF(COUNTA(E15:G15)>0,"세트 옵션은 세트만","OK"))),IF(INDEX('상품표'!$B$4:$B$18,MATCH(C15,'상품표'!$A$4:$A$18,0))="세트",IF(COUNTA(E15:G15)<3,"세트 옵션 선택",IF(D15<>"","사이즈 불필요","OK")),IF(COUNTA(E15:G15)>0,"세트 옵션은 세트만",IF(D15<>"","사이즈 불필요","OK"))))))))}
A16: 11 | I16: {=IF(C16="","",IFERROR(INDEX('상품표'!$C$4:$C$18,MATCH(C16,'상품표'!$A$4:$A$18,0)),""))} | J16: =IF(I16="","",ROUND(I16*(1-'상품표'!$G$4),0)) | K16: =IF(OR(J16="",H16=""),"",J16*H16) | L16: {=IF(C16="","",IF(ISNA(MATCH(C16,'상품표'!$A$4:$A$18,0)),"상품명 확인",IF(H16="","수량 입력",IF(FALSE,"",IF(INDEX('상품표'!$B$4:$B$18,MATCH(C16,'상품표'!$A$4:$A$18,0))="의류",IF(D16="","사이즈 선택",IF(AND(LEFT(C16,4)="후드집업",OR(D16="XXS",D16="XS")),"후드는 S부터",IF(COUNTA(E16:G16)>0,"세트 옵션은 세트만","OK"))),IF(INDEX('상품표'!$B$4:$B$18,MATCH(C16,'상품표'!$A$4:$A$18,0))="세트",IF(COUNTA(E16:G16)<3,"세트 옵션 선택",IF(D16<>"","사이즈 불필요","OK")),IF(COUNTA(E16:G16)>0,"세트 옵션은 세트만",IF(D16<>"","사이즈 불필요","OK"))))))))}
A17: 12 | I17: {=IF(C17="","",IFERROR(INDEX('상품표'!$C$4:$C$18,MATCH(C17,'상품표'!$A$4:$A$18,0)),""))} | J17: =IF(I17="","",ROUND(I17*(1-'상품표'!$G$4),0)) | K17: =IF(OR(J17="",H17=""),"",J17*H17) | L17: {=IF(C17="","",IF(ISNA(MATCH(C17,'상품표'!$A$4:$A$18,0)),"상품명 확인",IF(H17="","수량 입력",IF(FALSE,"",IF(INDEX('상품표'!$B$4:$B$18,MATCH(C17,'상품표'!$A$4:$A$18,0))="의류",IF(D17="","사이즈 선택",IF(AND(LEFT(C17,4)="후드집업",OR(D17="XXS",D17="XS")),"후드는 S부터",IF(COUNTA(E17:G17)>0,"세트 옵션은 세트만","OK"))),IF(INDEX('상품표'!$B$4:$B$18,MATCH(C17,'상품표'!$A$4:$A$18,0))="세트",IF(COUNTA(E17:G17)<3,"세트 옵션 선택",IF(D17<>"","사이즈 불필요","OK")),IF(COUNTA(E17:G17)>0,"세트 옵션은 세트만",IF(D17<>"","사이즈 불필요","OK"))))))))}
... A305: 300 | I305: {=IF(C305="","",IFERROR(INDEX('상품표'!$C$4:$C$18,MATCH(C305,'상품표'!$A$4:$A$18,0)),""))} | J305: =IF(I305="","",ROUND(I305*(1-'상품표'!$G$4),0)) | K305: =IF(OR(J305="",H305=""),"",J305*H305) | L305: {=IF(C305="","",IF(ISNA(MATCH(C305,'상품표'!$A$4:$A$18,0)),"상품명 확인",IF(H305="","수량 입력",IF(FALSE,"",IF(INDEX('상품표'!$B$4:$B$18,MATCH(C305,'상품표'!$A$4:$A$18,0))="의류",IF(D305="","사이즈 선택",IF(AND(LEFT(C305,4)="후드집업",OR(D305="XXS",D305="XS")),"후드는 S부터",IF(COUNTA(E305:G305)>0,"세트 옵션은 세트만","OK"))),IF(INDEX('상품표'!$B$4:$B$18,MATCH(C305,'상품표'!$A$4:$A$18,0))="세트",IF(COUNTA(E305:G305)<3,"세트 옵션 선택",IF(D305<>"","사이즈 불필요","OK")),IF(COUNTA(E305:G305)>0,"세트 옵션은 세트만",IF(D305<>"","사이즈 불필요","OK"))))))))}

Sheet 상품표
A1: 상품표 · 할인 설정 (스탭용)
A3: 상품 | B3: 분류 | C3: 정가(원) | D3: 사전구매가(원)
A4: 후드집업 - 그레이 | B4: 의류 | C4: 52000 | D4: =ROUND(C4*(1-$G$4),0) -> 46800 | F4: 사전구매 할인율 | G4: 0.1
A5: 후드집업 - 블랙 | B5: 의류 | C5: 52000 | D5: =ROUND(C5*(1-$G$4),0) -> 46800
A6: 그래픽 티셔츠 - 블랙 | B6: 의류 | C6: 30000 | D6: =ROUND(C6*(1-$G$4),0) -> 27000 | F6: 올인원 세트 구성
A7: 그래픽 티셔츠 - 화이트 | B7: 의류 | C7: 30000 | D7: =ROUND(C7*(1-$G$4),0) -> 27000 | F7: · 반다나 1 (레드 웨이브 / 블랙 스탬프 중 택1)
A8: 손수건 - 레드 웨이브 | B8: 잡화 | C8: 10000 | D8: =ROUND(C8*(1-$G$4),0) -> 9000 | F8: · 바쿠백 1 (블랙 / 화이트 중 택1)
A9: 손수건 - 블랙 스탬프 | B9: 잡화 | C9: 10000 | D9: =ROUND(C9*(1-$G$4),0) -> 9000 | F9: · 키링 1 (1 스탬프 / 2 십자가 중 택1)
A10: 바쿠백 - 블랙 | B10: 잡화 | C10: 10000 | D10: =ROUND(C10*(1-$G$4),0) -> 9000 | F10: · 핑거보드 키링 1
A11: 바쿠백 - 화이트 | B11: 잡화 | C11: 10000 | D11: =ROUND(C11*(1-$G$4),0) -> 9000 | F11: · 스티커팩 1
A12: 핑거보드 키링 | B12: 소품 | C12: 6000 | D12: =ROUND(C12*(1-$G$4),0) -> 5400 | F12: · 정가 합계 34,000원 / 세트가는 C18 칸에서 수정
A13: 키링 1 - 스탬프 | B13: 소품 | C13: 5000 | D13: =ROUND(C13*(1-$G$4),0) -> 4500
A14: 키링 2 - 십자가 | B14: 소품 | C14: 5000 | D14: =ROUND(C14*(1-$G$4),0) -> 4500
A15: 네임택 - 블랙 스탬프 | B15: 소품 | C15: 4500 | D15: =ROUND(C15*(1-$G$4),0) -> 4050
A16: 네임택 - 웨이브 | B16: 소품 | C16: 4500 | D16: =ROUND(C16*(1-$G$4),0) -> 4050
A17: 스티커팩 | B17: 소품 | C17: 3000 | D17: =ROUND(C17*(1-$G$4),0) -> 2700
A18: 올인원 세트 | B18: 세트 | C18: 32000 | D18: =ROUND(C18*(1-$G$4),0) -> 28800
A20: ※ 노란 칸(세트가, 사전구매 할인율) 수정 시 주문서 단가 전체에 반영 / 할인 순서: 정가(세트는 세트가) → 사전구매 10% 할인
